Workbook
Name 第一週工讀時數表: 表格1[]

Sheet week1
C3: 二月第一週哈士奇自行車工讀時數表
C4: 時段 | D4: 週一 | E4: 週二 | F4: 週三 | G4: 週四 | H4: 週五 | I4: 週六 | J4: 週日 | K4: 總計 | L4: 佔比
C5: 早上 | D5: 38 | E5: 42 | F5: 45 | G5: 38 | H5: 62 | I5: 69 | J5: 27 | K5: =SUM(D5:J5) -> 321 | L5: =K5/$K$9 -> 0.23126801
C6: 中午 | D6: 56 | E6: 36 | F6: 22 | G6: 48 | H6: 69 | I6: 78 | J6: 96 | K6: =SUM(D6:J6) -> 405 | L6: =K6/$K$9 -> 0.29178674
C7: 晚上 | D7: 42 | E7: 97 | F7: 15 | G7: 49 | H7: 58 | I7: 21 | J7: 32 | K7: =SUM(D7:J7) -> 314 | L7: =K7/$K$9 -> 0.22622478
C8: 凌晨 | D8: 33 | E8: 56 | F8: 43 | G8: 65 | H8: 72 | I8: 34 | J8: 45 | K8: =SUM(D8:J8) -> 348 | L8: =K8/$K$9 -> 0.25072046
C9: 總計 | D9: =SUM(D5:D8) -> 169 | E9: =SUM(E5:E8) -> 231 | F9: =SUM(F5:F8) -> 125 | G9: =SUM(G5:G8) -> 200 | H9: =SUM(H5:H8) -> 261 | I9: =SUM(I5:I8) -> 202 | J9: =SUM(J5:J8) -> 200 | K9: =SUM(D9:J9) -> 1388 | L9: =K9/$K$9 -> 1
C10: 佔比 | D10: =D9/$K$9 -> 0.12175793 | E10: =E9/$K$9 -> 0.16642651 | F10: =F9/$K$9 -> 0.090057637 | G10: =G9/$K$9 -> 0.14409222 | H10: =H9/$K$9 -> 0.18804035 | I10: =I9/$K$9 -> 0.14553314 | J10: =J9/$K$9 -> 0.14409222 | K10: =K9/$K$9 -> 1
C15: 二月第一週工讀費用表
C16: 時段 | D16: 週一 | E16: 週二 | F16: 週三 | G16: 週四 | H16: 週五 | I16: 週六 | J16: 週日 | K16: 總計 | L16: 佔比
C17: 早上 | D17: =D5*工讀金表!D5 -> 7600 | E17: =E5*工讀金表!E5 -> 8400 | F17: =F5*工讀金表!F5 -> 9000 | G17: =G5*工讀金表!G5 -> 7600 | H17: =H5*工讀金表!H5 -> 12400 | I17: =I5*工讀金表!I5 -> 17250 | J17: =J5*工讀金表!J5 -> 8100 | K17: =SUM(D17:J17) -> 70350 | L17: =K17/$K$21 -> 0.16602554
C18: 中午 | D18: =D6*工讀金表!D6 -> 11200 | E18: =E6*工讀金表!E6 -> 7200 | F18: =F6*工讀金表!F6 -> 4400 | G18: =G6*工讀金表!G6 -> 9600 | H18: =H6*工讀金表!H6 -> 13800 | I18: =I6*工讀金表!I6 -> 19500 | J18: =J6*工讀金表!J6 -> 28800 | K18: =SUM(D18:J18) -> 94500 | L18: =K18/$K$21 -> 0.22301938
C19: 晚上 | D19: =D7*工讀金表!D7 -> 13440 | E19: =E7*工讀金表!E7 -> 31040 | F19: =F7*工讀金表!F7 -> 4800 | G19: =G7*工讀金表!G7 -> 15680 | H19: =H7*工讀金表!H7 -> 18560 | I19: =I7*工讀金表!I7 -> 8400 | J19: =J7*工讀金表!J7 -> 15360 | K19: =SUM(D19:J19) -> 107280 | L19: =K19/$K$21 -> 0.25318009
C20: 凌晨 | D20: =D8*工讀金表!D8 -> 13200 | E20: =E8*工讀金表!E8 -> 22400 | F20: =F8*工讀金表!F8 -> 17200 | G20: =G8*工讀金表!G8 -> 26000 | H20: =H8*工讀金表!H8 -> 28800 | I20: =I8*工讀金表!I8 -> 17000 | J20: =J8*工讀金表!J8 -> 27000 | K20: =SUM(D20:J20) -> 151600 | L20: =K20/$K$21 -> 0.357775
K21: =SUM(K17:K20) -> 423730 | L21: =K21/$K$21 -> 1
C24: 工讀金表 | M24: Sumproduct
C25: 時段 | D25: 週一 | E25: 週二 | F25: 週三 | G25: 週四 | H25: 週五 | I25: 週六 | J25: 週日 | M25: 總和 | N25: =SUMPRODUCT(D5:J5,D26:J26) -> 70350
C26: 早上 | D26: 200 | E26: 200 | F26: 200 | G26: 200 | H26: 200 | I26: 250 | J26: 300 | N26: =SUMPRODUCT(D6:J6,D27:J27) -> 94500
C27: 中午 | D27: 200 | E27: 200 | F27: 200 | G27: 200 | H27: 200 | I27: 250 | J27: 300 | N27: =SUMPRODUCT(D7:J7,D28:J28) -> 107280
C28: 晚上 | D28: =D26*1.6 -> 320 | E28: =E26*1.6 -> 320 | F28: =F26*1.6 -> 320 | G28: =G26*1.6 -> 320 | H28: =H26*1.6 -> 320 | I28: =I26*1.6 -> 400 | J28: =J26*1.6 -> 480 | N28: =SUMPRODUCT(D8:J8,D29:J29) -> 151600
C29: 凌晨 | D29: =D26*2 -> 400 | E29: =E26*2 -> 400 | F29: =F26*2 -> 400 | G29: =G26*2 -> 400 | H29: =H26*2 -> 400 | I29: =I26*2 -> 500 | J29: =J26*2 -> 600

Sheet 工作表1
A3: 60 | B3: =IF(A3>=$F$3,$E$3,IF(A3>=$F$4,$E$4,IF(A3>=$F$5,$E$5,IF(A3>=$F$6,$E$6,$E$7)))) -> d | E3: a | F3: 90
A4: 58 | B4: =IF(A4>=$F$3,$E$3,IF(A4>=$F$4,$E$4,IF(A4>=$F$5,$E$5,IF(A4>=$F$6,$E$6,$E$7)))) -> e | E4: b | F4: 80
A5: 70 | B5: =IF(A5>=$F$3,$E$3,IF(A5>=$F$4,$E$4,IF(A5>=$F$5,$E$5,IF(A5>=$F$6,$E$6,$E$7)))) -> c | E5: c | F5: 70
A6: 88 | B6: =IF(A6>=$F$3,$E$3,IF(A6>=$F$4,$E$4,IF(A6>=$F$5,$E$5,IF(A6>=$F$6,$E$6,$E$7)))) -> b | E6: d | F6: 60
A7: 95 | B7: =IF(A7>=$F$3,$E$3,IF(A7>=$F$4,$E$4,IF(A7>=$F$5,$E$5,IF(A7>=$F$6,$E$6,$E$7)))) -> a | E7: e | F7: 不及格
A8: 47 | B8: =IF(A8>=$F$3,$E$3,IF(A8>=$F$4,$E$4,IF(A8>=$F$5,$E$5,IF(A8>=$F$6,$E$6,$E$7)))) -> e

Sheet week2
C3: 二月第二週哈士奇自行車工讀時數表
C4: 時段 | D4: 週一 | E4: 週二 | F4: 週三 | G4: 週四 | H4: 週五 | I4: 週六 | J4: 週日 | K4: 總計 | L4: 佔比
C5: 早上 | D5: =week1!D5+5 -> 43 | E5: =week1!E5+5 -> 47 | F5: =week1!F5+5 -> 50 | G5: =week1!G5+5 -> 43 | H5: =week1!H5+5 -> 67 | I5: =week1!I5+5 -> 74 | J5: =week1!J5+5 -> 32 | K5: =SUM(week2!$D5:$J5) -> 356 | L5: =week2!$K5/$K$9 -> 0.23298429
C6: 中午 | D6: =week1!D6+5 -> 61 | E6: =week1!E6+5 -> 41 | F6: =week1!F6+5 -> 27 | G6: =week1!G6+5 -> 53 | H6: =week1!H6+5 -> 74 | I6: =week1!I6+5 -> 83 | J6: =week1!J6+5 -> 101 | K6: =SUM(week2!$D6:$J6) -> 440 | L6: =week2!$K6/$K$9 -> 0.28795812
C7: 晚上 | D7: =week1!D7+5 -> 47 | E7: =week1!E7+5 -> 102 | F7: =week1!F7+5 -> 20 | G7: =week1!G7+5 -> 54 | H7: =week1!H7+5 -> 63 | I7: =week1!I7+5 -> 26 | J7: =week1!J7+5 -> 37 | K7: =SUM(week2!$D7:$J7) -> 349 | L7: =week2!$K7/$K$9 -> 0.22840314
C8: 凌晨 | D8: =week1!D8+5 -> 38 | E8: =week1!E8+5 -> 61 | F8: =week1!F8+5 -> 48 | G8: =week1!G8+5 -> 70 | H8: =week1!H8+5 -> 77 | I8: =week1!I8+5 -> 39 | J8: =week1!J8+5 -> 50 | K8: =SUM(week2!$D8:$J8) -> 383 | L8: =week2!$K8/$K$9 -> 0.25065445
C9: 總計 | D9: =SUM(D5:D8) -> 189 | E9: =SUM(E5:E8) -> 251 | F9: =SUM(F5:F8) -> 145 | G9: =SUM(G5:G8) -> 220 | H9: =SUM(H5:H8) -> 281 | I9: =SUM(I5:I8) -> 222 | J9: =SUM(J5:J8) -> 220 | K9: =SUM(week2!$D9:$J9) -> 1528 | L9: =week2!$K9/$K$9 -> 1
C10: 佔比 | D10: =D9/$K$9 -> 0.1236911 | E10: =E9/$K$9 -> 0.16426702 | F10: =F9/$K$9 -> 0.094895288 | G10: =G9/$K$9 -> 0.14397906 | H10: =H9/$K$9 -> 0.18390052 | I10: =I9/$K$9 -> 0.14528796 | J10: =J9/$K$9 -> 0.14397906 | K10: =K9/$K$9 -> 1
C13: 二月第一週工讀費用表
C14: 時段 | D14: 週一 | E14: 週二 | F14: 週三 | G14: 週四 | H14: 週五 | I14: 週六 | J14: 週日 | K14: 總計 | L14: 佔比
C15: 早上 | D15: =D5*工讀金表!D5 -> 8600 | E15: =E5*工讀金表!E5 -> 9400 | F15: =F5*工讀金表!F5 -> 10000 | H15: =H5*工讀金表!H5 -> 13400 | I15: =I5*工讀金表!I5 -> 18500 | J15: =J5*工讀金表!J5 -> 9600 | K15: =SUM(D15:J15) -> 69500 | L15: =K15/$K$19 -> 0.15157133
C16: 中午 | D16: =D6*工讀金表!D6 -> 12200 | E16: =E6*工讀金表!E6 -> 8200 | F16: =F6*工讀金表!F6 -> 5400 | G16: =G6*工讀金表!G6 -> 10600 | H16: =H6*工讀金表!H6 -> 14800 | I16: =I6*工讀金表!I6 -> 20750 | J16: =J6*工讀金表!J6 -> 30300 | K16: =SUM(D16:J16) -> 102250 | L16: =K16/$K$19 -> 0.22299522
C17: 晚上 | D17: =D7*工讀金表!D7 -> 15040 | E17: =E7*工讀金表!E7 -> 32640 | F17: =F7*工讀金表!F7 -> 6400 | G17: =G7*工讀金表!G7 -> 17280 | H17: =H7*工讀金表!H7 -> 20160 | I17: =I7*工讀金表!I7 -> 10400 | J17: =J7*工讀金表!J7 -> 17760 | K17: =SUM(D17:J17) -> 119680 | L17: =K17/$K$19 -> 0.261008
C18: 凌晨 | D18: =D8*工讀金表!D8 -> 15200 | E18: =E8*工讀金表!E8 -> 24400 | F18: =F8*工讀金表!F8 -> 19200 | G18: =G8*工讀金表!G8 -> 28000 | H18: =H8*工讀金表!H8 -> 30800 | I18: =I8*工讀金表!I8 -> 19500 | J18: =J8*工讀金表!J8 -> 30000 | K18: =SUM(D18:J18) -> 167100 | L18: =K18/$K$19 -> 0.36442545
K19: =SUM(K15:K18) -> 458530 | L19: =K19/$K$19 -> 1

Sheet week3
C3: 二月第三週哈士奇自行車工讀時數表
C4: 時段 | D4: 週一 | E4: 週二 | F4: 週三 | G4: 週四 | H4: 週五 | I4: 週六 | J4: 週日 | K4: 總計 | L4: 佔比
C5: 早上 | D5: =week1!D5+12 -> 50 | E5: =week1!E5+12 -> 54 | F5: =week1!F5+12 -> 57 | G5: =week1!G5+12 -> 50 | H5: =week1!H5+12 -> 74 | I5: =week1!I5+12 -> 81 | J5: =week1!J5+12 -> 39 | K5: =SUM(week3!$D5:$J5) -> 405 | L5: =week3!$K5/$K$9 -> 0.23491879
C6: 中午 | D6: =week1!D6+12 -> 68 | E6: =week1!E6+12 -> 48 | F6: =week1!F6+12 -> 34 | G6: =week1!G6+12 -> 60 | H6: =week1!H6+12 -> 81 | I6: =week1!I6+12 -> 90 | J6: =week1!J6+12 -> 108 | K6: =SUM(week3!$D6:$J6) -> 489 | L6: =week3!$K6/$K$9 -> 0.28364269
C7: 晚上 | D7: =week1!D7+12 -> 54 | E7: =week1!E7+12 -> 109 | F7: =week1!F7+12 -> 27 | G7: =week1!G7+12 -> 61 | H7: =week1!H7+12 -> 70 | I7: =week1!I7+12 -> 33 | J7: =week1!J7+12 -> 44 | K7: =SUM(week3!$D7:$J7) -> 398 | L7: =week3!$K7/$K$9 -> 0.23085847
C8: 凌晨 | D8: =week1!D8+12 -> 45 | E8: =week1!E8+12 -> 68 | F8: =week1!F8+12 -> 55 | G8: =week1!G8+12 -> 77 | H8: =week1!H8+12 -> 84 | I8: =week1!I8+12 -> 46 | J8: =week1!J8+12 -> 57 | K8: =SUM(week3!$D8:$J8) -> 432 | L8: =week3!$K8/$K$9 -> 0.25058005
C9: 總計 | D9: =SUM(D5:D8) -> 217 | E9: =SUM(E5:E8) -> 279 | F9: =SUM(F5:F8) -> 173 | G9: =SUM(G5:G8) -> 248 | H9: =SUM(H5:H8) -> 309 | I9: =SUM(I5:I8) -> 250 | J9: =SUM(J5:J8) -> 248 | K9: =SUM(week3!$D9:$J9) -> 1724 | L9: =week3!$K9/$K$9 -> 1
C10: 佔比 | D10: =D9/$K$9 -> 0.12587007 | E10: =E9/$K$9 -> 0.16183295 | F10: =F9/$K$9 -> 0.10034803 | G10: =G9/$K$9 -> 0.14385151 | H10: =H9/$K$9 -> 0.17923434 | I10: =I9/$K$9 -> 0.1450116 | J10: =J9/$K$9 -> 0.14385151 | K10: =K9/$K$9 -> 1
C13: 二月第一週工讀費用表
C14: 時段 | D14: 週一 | E14: 週二 | F14: 週三 | G14: 週四 | H14: 週五 | I14: 週六 | J14: 週日 | K14: 總計 | L14: 佔比
C15: 早上 | D15: =D5*工讀金表!D5 -> 10000 | E15: =E5*工讀金表!E5 -> 10800 | F15: =F5*工讀金表!F5 -> 11400 | H15: =H5*工讀金表!H5 -> 14800 | I15: =I5*工讀金表!I5 -> 20250 | J15: =J5*工讀金表!J5 -> 11700 | K15: =SUM(D15:J15) -> 78950 | L15: =K15/$K$19 -> 0.1524455
C16: 中午 | D16: =D6*工讀金表!D6 -> 13600 | E16: =E6*工讀金表!E6 -> 9600 | F16: =F6*工讀金表!F6 -> 6800 | G16: =G6*工讀金表!G6 -> 12000 | H16: =H6*工讀金表!H6 -> 16200 | I16: =I6*工讀金表!I6 -> 22500 | J16: =J6*工讀金表!J6 -> 32400 | K16: =SUM(D16:J16) -> 113100 | L16: =K16/$K$19 -> 0.21838614
C17: 晚上 | D17: =D7*工讀金表!D7 -> 17280 | E17: =E7*工讀金表!E7 -> 34880 | F17: =F7*工讀金表!F7 -> 8640 | G17: =G7*工讀金表!G7 -> 19520 | H17: =H7*工讀金表!H7 -> 22400 | I17: =I7*工讀金表!I7 -> 13200 | J17: =J7*工讀金表!J7 -> 21120 | K17: =SUM(D17:J17) -> 137040 | L17: =K17/$K$19 -> 0.26461218
C18: 凌晨 | D18: =D8*工讀金表!D8 -> 18000 | E18: =E8*工讀金表!E8 -> 27200 | F18: =F8*工讀金表!F8 -> 22000 | G18: =G8*工讀金表!G8 -> 30800 | H18: =H8*工讀金表!H8 -> 33600 | I18: =I8*工讀金表!I8 -> 23000 | J18: =J8*工讀金表!J8 -> 34200 | K18: =SUM(D18:J18) -> 188800 | L18: =K18/$K$19 -> 0.36455618
K19: =SUM(K15:K18) -> 517890 | L19: =K19/$K$19 -> 1

Sheet week4
C3: 二月第一週哈士奇自行車工讀時數表
C4: 時段 | D4: 週一 | E4: 週二 | F4: 週三 | G4: 週四 | H4: 週五 | I4: 週六 | J4: 週日 | K4: 總計 | L4: 佔比
C5: 早上 | D5: =week1!D5-6 -> 32 | E5: =week1!E5-6 -> 36 | F5: =week1!F5-6 -> 39 | G5: =week1!G5-6 -> 32 | H5: =week1!H5-6 -> 56 | I5: =week1!I5-6 -> 63 | J5: =week1!J5-6 -> 21 | K5: =SUM(week4!$D5:$J5) -> 279 | L5: =week4!$K5/$K$9 -> 0.22868852 | P5: 45292 | Q5: 1 | R5: 1 | S5: 星期一
C6: 中午 | D6: =week1!D6-6 -> 50 | E6: =week1!E6-6 -> 30 | F6: =week1!F6-6 -> 16 | G6: =week1!G6-6 -> 42 | H6: =week1!H6-6 -> 63 | I6: =week1!I6-6 -> 72 | J6: =week1!J6-6 -> 90 | K6: =SUM(week4!$D6:$J6) -> 363 | L6: =week4!$K6/$K$9 -> 0.29754098 | P6: 45293 | Q6: 2 | R6: 2 | S6: 星期二
C7: 晚上 | D7: =week1!D7-6 -> 36 | E7: =week1!E7-6 -> 91 | F7: =week1!F7-6 -> 9 | G7: =week1!G7-6 -> 43 | H7: =week1!H7-6 -> 52 | I7: =week1!I7-6 -> 15 | J7: =week1!J7-6 -> 26 | K7: =SUM(week4!$D7:$J7) -> 272 | L7: =week4!$K7/$K$9 -> 0.22295082 | P7: 45294 | Q7: 4 | R7: 3 | S7: 星期三
C8: 凌晨 | D8: =week1!D8-6 -> 27 | E8: =week1!E8-6 -> 50 | F8: =week1!F8-6 -> 37 | G8: =week1!G8-6 -> 59 | H8: =week1!H8-6 -> 66 | I8: =week1!I8-6 -> 28 | J8: =week1!J8-6 -> 39 | K8: =SUM(week4!$D8:$J8) -> 306 | L8: =week4!$K8/$K$9 -> 0.25081967 | P8: 45295 | Q8: 8 | R8: 4 | S8: 星期四
C9: 總計 | D9: =SUM(D5:D8) -> 145 | E9: =SUM(E5:E8) -> 207 | F9: =SUM(F5:F8) -> 101 | G9: =SUM(G5:G8) -> 176 | H9: =SUM(H5:H8) -> 237 | I9: =SUM(I5:I8) -> 178 | J9: =SUM(J5:J8) -> 176 | K9: =SUM(week4!$D9:$J9) -> 1220 | L9: =week4!$K9/$K$9 -> 1 | P9: 45296 | Q9: 16 | R9: 5 | S9: 星期五
C10: 佔比 | D10: =D9/$K$9 -> 0.11885246 | E10: =E9/$K$9 -> 0.16967213 | F10: =F9/$K$9 -> 0.082786885 | G10: =G9/$K$9 -> 0.1442623 | H10: =H9/$K$9 -> 0.1942623 | I10: =I9/$K$9 -> 0.14590164 | J10: =J9/$K$9 -> 0.1442623 | K10: =K9/$K$9 -> 1 | P10: 45297 | Q10: 32 | R10: 6 | S10: 星期六
P11: 45298 | Q11: 64 | R11: 7 | S11: 星期日
P12: 45299 | Q12: 128 | R12: 8 | S12: 星期一
C13: 二月第一週工讀費用表 | P13: 45300 | Q13: 256 | R13: 9 | S13: 星期二
C14: 時段 | D14: 週一 | E14: 週二 | F14: 週三 | G14: 週四 | H14: 週五 | I14: 週六 | J14: 週日 | K14: 總計 | L14: 佔比 | P14: 45301 | Q14: 512 | R14: 10 | S14: 星期三
C15: 早上 | D15: =D5*工讀金表!D5 -> 6400 | E15: =E5*工讀金表!E5 -> 7200 | F15: =F5*工讀金表!F5 -> 7800 | H15: =H5*工讀金表!H5 -> 11200 | I15: =I5*工讀金表!I5 -> 15750 | J15: =J5*工讀金表!J5 -> 6300 | K15: =SUM(D15:J15) -> 54650 | L15: =K15/$K$19 -> 0.14962355 | P15: 45302 | Q15: 1024 | R15: 11 | S15: 星期四
C16: 中午 | D16: =D6*工讀金表!D6 -> 10000 | E16: =E6*工讀金表!E6 -> 6000 | F16: =F6*工讀金表!F6 -> 3200 | G16: =G6*工讀金表!G6 -> 8400 | H16: =H6*工讀金表!H6 -> 12600 | I16: =I6*工讀金表!I6 -> 18000 | J16: =J6*工讀金表!J6 -> 27000 | K16: =SUM(D16:J16) -> 85200 | L16: =K16/$K$19 -> 0.23326489 | P16: 45303 | Q16: 2048 | R16: 12 | S16: 星期五
C17: 晚上 | D17: =D7*工讀金表!D7 -> 11520 | E17: =E7*工讀金表!E7 -> 29120 | F17: =F7*工讀金表!F7 -> 2880 | G17: =G7*工讀金表!G7 -> 13760 | H17: =H7*工讀金表!H7 -> 16640 | I17: =I7*工讀金表!I7 -> 6000 | J17: =J7*工讀金表!J7 -> 12480 | K17: =SUM(D17:J17) -> 92400 | L17: =K17/$K$19 -> 0.25297741 | P17: 45304 | Q17: 4096 | R17: 13 | S17: 星期六
C18: 凌晨 | D18: =D8*工讀金表!D8 -> 10800 | E18: =E8*工讀金表!E8 -> 20000 | F18: =F8*工讀金表!F8 -> 14800 | G18: =G8*工讀金表!G8 -> 23600 | H18: =H8*工讀金表!H8 -> 26400 | I18: =I8*工讀金表!I8 -> 14000 | J18: =J8*工讀金表!J8 -> 23400 | K18: =SUM(D18:J18) -> 133000 | L18: =K18/$K$19 -> 0.36413415 | P18: 45305 | Q18: 8192 | R18: 14 | S18: 星期日
K19: =SUM(K15:K18) -> 365250 | L19: =K19/$K$19 -> 1 | P19: 45306 | Q19: 16384 | R19: 15 | S19: 星期一
P20: 45307 | Q20: 32768 | R20: 16 | S20: 星期二
P21: 45308 | Q21: 65536 | R21: 17 | S21: 星期三
P22: 45309 | Q22: 131072 | R22: 18 | S22: 星期四
P23: 45310 | R23: 19 | S23: 星期五
P24: 45311 | R24: 20 | S24: 星期六
P25: 45312 | R25: 21 | S25: 星期日
P26: 45313 | R26: 22 | S26: 星期一
P27: 45314 | R27: 23 | S27: 星期二
P28: 45315 | R28: 24
P29: 45316 | R29: 25
P30: 45317 | R30: 26
P31: 45318 | R31: 27
P32: 45319 | R32: 28
P33: 45320 | R33: 29
P34: 45321 | R34: 30
P35: 45322 | R35: 31
P36: 45323 | R36: 32
P37: 45324 | R37: 33
P38: 45325 | R38: 34
P39: 45326 | R39: 35
R40: 36
R41: 37
R42: 38
...

Sheet 工讀金表
C3: 工讀金表
C4: 時段 | D4: 週一 | E4: 週二 | F4: 週三 | G4: 週四 | H4: 週五 | I4: 週六 | J4: 週日
C5: 早上 | D5: 200 | E5: 200 | F5: 200 | G5: 200 | H5: 200 | I5: 250 | J5: 300
C6: 中午 | D6: 200 | E6: 200 | F6: 200 | G6: 200 | H6: 200 | I6: 250 | J6: 300
C7: 晚上 | D7: =D5*1.6 -> 320 | E7: =E5*1.6 -> 320 | F7: =F5*1.6 -> 320 | G7: =G5*1.6 -> 320 | H7: =H5*1.6 -> 320 | I7: =I5*1.6 -> 400 | J7: =J5*1.6 -> 480
C8: 凌晨 | D8: =D5*2 -> 400 | E8: =E5*2 -> 400 | F8: =F5*2 -> 400 | G8: =G5*2 -> 400 | H8: =H5*2 -> 400 | I8: =I5*2 -> 500 | J8: =J5*2 -> 600

Sheet Feb
C3: 二月哈士奇自行車工讀時數表
C4: 時段 | D4: 週一 | E4: 週二 | F4: 週三 | G4: 週四 | H4: 週五 | I4: 週六 | J4: 週日 | K4: 總計 | L4: 佔比
C5: 早上 | D5: =SUM(week1:week4!D5) -> 163 | E5: =SUM(week1:week4!E5) -> 179 | F5: =SUM(week1:week4!F5) -> 261 | G5: =SUM(week1:week4!G5) -> 163 | H5: =SUM(week1:week4!H5) -> 259 | I5: =SUM(week1:week4!I5) -> 287 | J5: =SUM(week1:week4!J5) -> 119 | K5: =SUM(表格1_11[[#This Row],[週一]:[週日]]) -> 1431 | L5: =表格1_11[[#This Row],[總計]]/$K$9 -> 0.24419795
C6: 中午 | D6: =SUM(week1:week4!D6) -> 235 | E6: =SUM(week1:week4!E6) -> 155 | F6: =SUM(week1:week4!F6) -> 159 | G6: =SUM(week1:week4!G6) -> 203 | H6: =SUM(week1:week4!H6) -> 287 | I6: =SUM(week1:week4!I6) -> 323 | J6: =SUM(week1:week4!J6) -> 395 | K6: =SUM(表格1_11[[#This Row],[週一]:[週日]]) -> 1757 | L6: =表格1_11[[#This Row],[總計]]/$K$9 -> 0.29982935
C7: 晚上 | D7: =SUM(week1:week4!D7) -> 179 | E7: =SUM(week1:week4!E7) -> 399 | F7: =SUM(week1:week4!F7) -> 71 | G7: =SUM(week1:week4!G7) -> 207 | H7: =SUM(week1:week4!H7) -> 243 | I7: =SUM(week1:week4!I7) -> 95 | J7: =SUM(week1:week4!J7) -> 139 | K7: =SUM(表格1_11[[#This Row],[週一]:[週日]]) -> 1333 | L7: =表格1_11[[#This Row],[總計]]/$K$9 -> 0.2274744
C8: 凌晨 | D8: =SUM(week1:week4!D8) -> 143 | E8: =SUM(week1:week4!E8) -> 235 | F8: =SUM(week1:week4!F8) -> 183 | G8: =SUM(week1:week4!G8) -> 271 | H8: =SUM(week1:week4!H8) -> 299 | I8: =SUM(week1:week4!I8) -> 147 | J8: =SUM(week1:week4!J8) -> 191 | K8: =SUM(表格1_11[[#This Row],[週一]:[週日]]) -> 1469 | L8: =表格1_11[[#This Row],[總計]]/$K$9 -> 0.25068259
C9: 總計 | D9: =SUM(week1:week4!D9) -> 720 | E9: =SUM(week1:week4!E9) -> 968 | F9: =SUM(week1:week4!F9) -> 544 | G9: =SUM(week1:week4!G9) -> 844 | H9: =SUM(week1:week4!H9) -> 1088 | I9: =SUM(week1:week4!I9) -> 852 | J9: =SUM(week1:week4!J9) -> 844 | K9: =SUM(表格1_11[[#This Row],[週一]:[週日]]) -> 5860 | L9: =表格1_11[[#This Row],[總計]]/$K$9 -> 1
C10: 佔比 | D10: =D9/$K$9 -> 0.12286689 | E10: =E9/$K$9 -> 0.16518771 | F10: =F9/$K$9 -> 0.092832765 | G10: =G9/$K$9 -> 0.1440273 | H10: =H9/$K$9 -> 0.18566553 | I10: =I9/$K$9 -> 0.14539249 | J10: =J9/$K$9 -> 0.1440273 | K10: =K9/$K$9 -> 1
C15: 二月工讀費用表
C16: 時段 | D16: 週一 | E16: 週二 | F16: 週三 | G16: 週四 | H16: 週五 | I16: 週六 | J16: 週日 | K16: 總計 | L16: 佔比
C17: 早上 | D17: =D5*工讀金表!D5 -> 32600 | E17: =E5*工讀金表!E5 -> 35800 | F17: =F5*工讀金表!F5 -> 52200 | G17: =G5*工讀金表!G5 -> 32600 | H17: =H5*工讀金表!H5 -> 51800 | I17: =I5*工讀金表!I5 -> 71750 | J17: =J5*工讀金表!J5 -> 35700 | K17: =SUM(Feb!$D17:$J17) -> 312450 | L17: =Feb!$K17/Feb!$K$21 -> 0.17201608
C18: 中午 | D18: =D6*工讀金表!D6 -> 47000 | E18: =E6*工讀金表!E6 -> 31000 | F18: =F6*工讀金表!F6 -> 31800 | G18: =G6*工讀金表!G6 -> 40600 | H18: =H6*工讀金表!H6 -> 57400 | I18: =I6*工讀金表!I6 -> 80750 | J18: =J6*工讀金表!J6 -> 118500 | K18: =SUM(Feb!$D18:$J18) -> 407050 | L18: =Feb!$K18/Feb!$K$21 -> 0.22409712
C19: 晚上 | D19: =D7*工讀金表!D7 -> 57280 | E19: =E7*工讀金表!E7 -> 127680 | F19: =F7*工讀金表!F7 -> 22720 | G19: =G7*工讀金表!G7 -> 66240 | H19: =H7*工讀金表!H7 -> 77760 | I19: =I7*工讀金表!I7 -> 38000 | J19: =J7*工讀金表!J7 -> 66720 | K19: =SUM(Feb!$D19:$J19) -> 456400 | L19: =Feb!$K19/Feb!$K$21 -> 0.25126624
C20: 凌晨 | D20: =D8*工讀金表!D8 -> 57200 | E20: =E8*工讀金表!E8 -> 94000 | F20: =F8*工讀金表!F8 -> 73200 | G20: =G8*工讀金表!G8 -> 108400 | H20: =H8*工讀金表!H8 -> 119600 | I20: =I8*工讀金表!I8 -> 73500 | J20: =J8*工讀金表!J8 -> 114600 | K20: =SUM(Feb!$D20:$J20) -> 640500 | L20: =Feb!$K20/Feb!$K$21 -> 0.35262057
K21: =SUM(Feb!$K$17:$K$20) -> 1816400 | L21: 100%

Sheet 99
D2: 1 | E2: 2 | F2: 3 | G2: 4 | H2: 5 | I2: 6 | J2: 7 | K2: 8 | L2: 9
C3: 1 | D3: =$C3*D$2 -> 1 | E3: =$C3*E$2 -> 2 | F3: =$C3*F$2 -> 3 | G3: =$C3*G$2 -> 4 | H3: =$C3*H$2 -> 5 | I3: =$C3*I$2 -> 6 | J3: =$C3*J$2 -> 7 | K3: =$C3*K$2 -> 8 | L3: =$C3*L$2 -> 9
C4: 2 | D4: =$C4*D$2 -> 2 | E4: =$C4*E$2 -> 4 | F4: =$C4*F$2 -> 6 | G4: =$C4*G$2 -> 8 | H4: =$C4*H$2 -> 10 | I4: =$C4*I$2 -> 12 | J4: =$C4*J$2 -> 14 | K4: =$C4*K$2 -> 16 | L4: =$C4*L$2 -> 18
C5: 3 | D5: =$C5*D$2 -> 3 | E5: =$C5*E$2 -> 6 | F5: =$C5*F$2 -> 9 | G5: =$C5*G$2 -> 12 | H5: =$C5*H$2 -> 15 | I5: =$C5*I$2 -> 18 | J5: =$C5*J$2 -> 21 | K5: =$C5*K$2 -> 24 | L5: =$C5*L$2 -> 27
C6: 4 | D6: =$C6*D$2 -> 4 | E6: =$C6*E$2 -> 8 | F6: =$C6*F$2 -> 12 | G6: =$C6*G$2 -> 16 | H6: =$C6*H$2 -> 20 | I6: =$C6*I$2 -> 24 | J6: =$C6*J$2 -> 28 | K6: =$C6*K$2 -> 32 | L6: =$C6*L$2 -> 36
C7: 5 | D7: =$C7*D$2 -> 5 | E7: =$C7*E$2 -> 10 | F7: =$C7*F$2 -> 15 | G7: =$C7*G$2 -> 20 | H7: =$C7*H$2 -> 25 | I7: =$C7*I$2 -> 30 | J7: =$C7*J$2 -> 35 | K7: =$C7*K$2 -> 40 | L7: =$C7*L$2 -> 45
C8: 6 | D8: =$C8*D$2 -> 6 | E8: =$C8*E$2 -> 12 | F8: =$C8*F$2 -> 18 | G8: =$C8*G$2 -> 24 | H8: =$C8*H$2 -> 30 | I8: =$C8*I$2 -> 36 | J8: =$C8*J$2 -> 42 | K8: =$C8*K$2 -> 48 | L8: =$C8*L$2 -> 54
C9: 7 | D9: =$C9*D$2 -> 7 | E9: =$C9*E$2 -> 14 | F9: =$C9*F$2 -> 21 | G9: =$C9*G$2 -> 28 | H9: =$C9*H$2 -> 35 | I9: =$C9*I$2 -> 42 | J9: =$C9*J$2 -> 49 | K9: =$C9*K$2 -> 56 | L9: =$C9*L$2 -> 63
C10: 8 | D10: =$C10*D$2 -> 8 | E10: =$C10*E$2 -> 16 | F10: =$C10*F$2 -> 24 | G10: =$C10*G$2 -> 32 | H10: =$C10*H$2 -> 40 | I10: =$C10*I$2 -> 48 | J10: =$C10*J$2 -> 56 | K10: =$C10*K$2 -> 64 | L10: =$C10*L$2 -> 72
C11: 9 | D11: =$C11*D$2 -> 9 | E11: =$C11*E$2 -> 18 | F11: =$C11*F$2 -> 27 | G11: =$C11*G$2 -> 36 | H11: =$C11*H$2 -> 45 | I11: =$C11*I$2 -> 54 | J11: =$C11*J$2 -> 63 | K11: =$C11*K$2 -> 72 | L11: =$C11*L$2 -> 81
C14: 60
C15: 90
C16: 56
